<?xml version="1.0"?>
<robot name="AeroArmRobot">
 <link name="base_link">
    <inertial>
      <origin xyz="0.0 0 0" rpy="0 0 0"/>
      <mass value="2.24862"/>
      <inertia ixx="0.00787462" ixy="1.86853e-06" ixz="0.000109278" iyy="0.00564958" iyz="4.77298e-06" izz="0.00724112"/>
    </inertial>
    <visual>
      <origin xyz="0 0 0.01" rpy="0 0 0"/>
      <geometry>
        <mesh filename="package://aero_description/models/aero_arm_meshes/SEED-ARM_base.stl"scale="0.001 0.001 0.001"/>
      </geometry>
      <material name="Assy_Waist_1_color">
        <color rgba="0.74902 0.74902 0.74902 1.0"/>
      </material>
    </visual>
    <collision>
      <origin xyz="0 0 0.01" rpy="0 0 0"/>
      <geometry>
        <mesh filename="package://aero_description/models/aero_arm_meshes/SEED-ARM_base.stl"scale="0.001 0.001 0.001"/>
      </geometry>
    </collision>
  </link>
  <link name="r_shoulder_link">
    <inertial>
      <origin xyz="0 0 0" rpy="0 0 0"/>
      <mass value="0.153989"/>
      <inertia ixx="7.20502e-05" ixy="-3.97093e-11" ixz="1.25067e-06" iyy="9.14657e-05" iyz="1.33728e-10" izz="7.99165e-05"/>
    </inertial>
    <visual>
      <origin xyz="0  0 0" rpy="0 0 0"/>
      <geometry>
        <mesh filename="package://aero_description/models/aero_arm_meshes/SEED-ARM_shoulder-y.stl"scale="0.001 0.001 0.001"/>
      </geometry>
      <material name="Link1_1_color">
        <color rgba="0.74902 0.74902 0.74902 1.0"/>
      </material>
    </visual>
    <collision>
      <origin xyz="0 0 0" rpy="0 0 0"/>
      <geometry>
        <mesh filename="package://aero_description/models/aero_arm_meshes/SEED-ARM_shoulder-y.stl"scale="0.001 0.001 0.001"/>
      </geometry>
    </collision>
  </link>
<link name="leg_foreleg_link">
<visual>
<origin xyz="-0.0212 0.0 0.04" rpy="0 -0 0"/>
<geometry>
<mesh filename="package://aero_description/models/aero_arm_meshes/Lifter_foreleg.stl" scale="0.001 0.001 0.001"/>
</geometry>
<material name="Assy_LEG_LINK2_color">
<color rgba="0.8 0.8 0.8 1.0"/>
</material>
</visual>
<collision>
<origin xyz="-0.0212 0.0 0.045" rpy="0 -0 0"/>
<geometry>
<mesh filename="package://aero_description/models/aero_arm_meshes/Lifter_foreleg.stl" scale="0.001 0.001 0.001"/>
</geometry>
</collision>
<inertial>
<mass value="2.06679" />
<origin xyz="0.081713 0.000812 -0.146934" rpy="0 -0 0"/>
<inertia ixx="0.0408818" ixy="-9.39301e-06" ixz="-0.000750165" iyy="0.0403969" iyz="-0.000120419" izz="0.00260982"/>
</inertial>
</link>
<gazebo reference="leg_foreleg_link">
<mu1>0.9</mu1>
<mu2>0.9</mu2>
</gazebo>
<link name="leg_thigh_link">
<visual>
<origin xyz="0.0 0.0 -0.243" rpy="0 -0 0"/>
<geometry>
<mesh filename="package://aero_description/models/aero_arm_meshes/Lifter_thigh.stl" scale="0.001 0.001 0.001"/>
</geometry>
<material name="Assy_LEG_LINK1_color">
<color rgba="0.6 0.6 0.6 1.0"/>
</material>
</visual>
<collision>
<origin xyz="0.0 0.0 -0.243" rpy="0 -0 0"/>
<geometry>
<mesh filename="package://aero_description/models/aero_arm_meshes/Lifter_thigh.stl" scale="0.001 0.001 0.001"/>
</geometry>
</collision>
<inertial>
<mass value="2.62321" />
<origin xyz="0.0587169 0 -0.135292" rpy="0 -0 0"/>
<inertia ixx="0.0161595" ixy="-9.27234e-05" ixz="0.00262839" iyy="0.0166415" iyz="-0.00017447" izz="0.00477281"/>
</inertial>
</link>
<gazebo reference="leg_thigh_link">
<mu1>0.9</mu1>
<mu2>0.9</mu2>
</gazebo>
<link name="leg_base_link">
<visual>
<origin xyz="0 0 -0.01" rpy="0 -0 0"/>
<geometry>
<mesh filename="package://aero_description/models/aero_arm_meshes/CRT_arm_base_plate.stl" scale="0.001 0.001 0.001"/>
</geometry>
</visual>
<material name="Assy_WAIST_LINK1_color">
<color rgba="0.74902 0.74902 0.74902 1.0"/>
</material>
<collision>
<origin xyz="0 0 -0.01" rpy="0 -0 0"/>
<geometry>
<mesh filename="package://aero_description/models/aero_arm_meshes/CRT_arm_base_plate.stl" scale="0.001 0.001 0.001"/>
</geometry>
</collision>
<inertial>
<mass value="7.64604" />
<origin xyz="-0.012819 -0.002679 0.007207" rpy="0 -0 0"/>
<inertia ixx="0.0658136" ixy="-0.000159462" ixz="0.010103" iyy="0.0504268" iyz="0.000173435" izz="0.0889772"/>
</inertial>
</link>
<gazebo reference="leg_base_link">
<mu1>0.9</mu1>
<mu2>0.9</mu2>
</gazebo>
  <joint name="r_shoulder_y_joint" type="continuous">
    <origin xyz="0.0 0 0.01" rpy="0 0 0"/>
    <parent link="base_link"/>
	<axis xyz="0.0 0.0 1.0"/>
    <child link="r_shoulder_link"/>
    <dynamics damping="0.1"/>
  </joint>
  <link name="head_base_link">
    <inertial>
      <origin xyz="0 0 0" rpy="0 0 0"/>
      <mass value="1"/>
      <inertia ixx="0" ixy="0" ixz="0" iyy="0" iyz="0" izz="0"/>
    </inertial>
    <visual>
      <origin xyz="0 0 0" rpy="0 0 0"/>
      <geometry>
        <mesh filename="package://aero_description/models/aero_arm_meshes/PS4eye.STL"/>
      </geometry>
      <material name="head_base_link_color">
        <color rgba="1.0 1.0 1.0 1.0"/>
      </material>
    </visual>
    <collision>
      <origin xyz="0 0 0" rpy="0 0 0"/>
      <geometry>
        <mesh filename="package://aero_description/models/aero_arm_meshes/PS4eye.STL"/>
      </geometry>
    </collision>
  </link>
  <joint name="Camera" type="fixed">
    <origin xyz="0.067069 0 0.0235" rpy="0 0 0"/>
    <parent link="base_link"/>
    <child link="head_base_link"/>
    <dynamics damping="0.1"/>
  </joint>
  <link name="r_upperarm_link">
    <inertial>
      <origin xyz="0 0 0" rpy="0 0 0"/>
      <mass value="0.571747"/>
      <inertia ixx="0.00600119" ixy="-3.64499e-07" ixz="-0.000211137" iyy="0.00635549" iyz="-1.81458e-07" izz="0.000838023"/>
    </inertial>
    <visual>
      <origin xyz="0 0 -0.1205" rpy="0 0 0"/>
      <geometry>
        <mesh filename="package://aero_description/models/aero_arm_meshes/SEED-ARM_upper_arm.stl"scale="0.001 0.001 0.001"/>
      </geometry>
      <material name="Link2_1_color">
        <color rgba="0.74902 0.74902 0.74902 1.0"/>
      </material>
    </visual>
    <collision>
      <origin xyz="0 0 -0.1205" rpy="0 0 0"/>
      <geometry>
        <mesh filename="package://aero_description/models/aero_arm_meshes/SEED-ARM_upper_arm.stl"scale="0.001 0.001 0.001"/>
      </geometry>
    </collision>
  </link>
  <joint name="r_shoulder_p_joint" type="continuous">
    <origin xyz="0 0 0.1205" rpy="0 0 0"/>
	<axis xyz="0.0 1.0 0.0"/>    
	<parent link="r_shoulder_link"/>
    <child link="r_upperarm_link"/>
    <dynamics damping="0.1"/>
  </joint>
  <link name="r_elbow_link">
    <inertial>
      <origin xyz="0 0 0" rpy="0 0 0"/>
      <mass value="0.243133"/>
      <inertia ixx="0.000350355" ixy="0.0" ixz="-2.93419e-05" iyy="0.000370775" iyz="0.0" izz="0.00014505"/>
    </inertial>
    <visual>
      <origin xyz="0 0 -0.4205" rpy="0 0 0"/>
      <geometry>
        <mesh filename="package://aero_description/models/aero_arm_meshes/SEED-ARM_elbow.stl"scale="0.001 0.001 0.001"/>
      </geometry>
      <material name="Link3_1_color">
        <color rgba="0 0 0.6 1.0"/>
      </material>
    </visual>
    <collision>
      <origin xyz="0 0 -0.4205" rpy="0 0 0"/>
      <geometry>
        <mesh filename="package://aero_description/models/aero_arm_meshes/SEED-ARM_elbow.stl"scale="0.001 0.001 0.001"/>
      </geometry>
    </collision>
  </link>
  <joint name="r_elbow_joint" type="continuous">
    <origin xyz="0 0 0.3" rpy="0 0 0"/>
	<axis xyz="0.0 1.0 0.0"/>
    <parent link="r_upperarm_link"/>
    <child link="r_elbow_link"/>
    <dynamics damping="0.1"/>
  </joint>
  <link name="r_forearm_link">
    <inertial>
      <origin xyz="0 0 0" rpy="0 0 0"/>
      <mass value="0.520191"/>
      <inertia ixx="0.000719932" ixy="-1.77744e-08" ixz="1.34362e-06" iyy="0.000716013" iyz="-6.86778e-06" izz="0.000201071"/>
    </inertial>
    <visual>
      <origin xyz="0 0 -0.4805" rpy="0 0 0"/>
      <geometry>
        <mesh filename="package://aero_description/models/aero_arm_meshes/SEED-ARM_HA35.stl"scale="0.001 0.001 0.001"/>
      </geometry>
      <material name="Link5_1_color">
        <color rgba="0.74902 0.74902 0.74902 1.0"/>
      </material>
    </visual>
    <collision>
      <origin xyz="0 0 -0.4805" rpy="0 0 0"/>
      <geometry>
        <mesh filename="package://aero_description/models/aero_arm_meshes/SEED-ARM_HA35.stl"scale="0.001 0.001 0.001"/>
      </geometry>
    </collision>
  </link>
  <joint name="r_elbow2_joint" type="continuous">
    <origin xyz="0 0 0.06" rpy="0 0 0"/>
    <axis xyz="0.0 -1.0 0.0"/>
    <parent link="r_elbow_link"/>
    <child link="r_forearm_link"/>
    <dynamics damping="0.1"/>
	<mimic joint="r_elbow_joint" multiplier="-1" offset="0" />
  </joint>
  <link name="r_wrist_y_link">
    <inertial>
      <origin xyz="0 0 0" rpy="0 0 0"/>
      <mass value="0.148468"/>
      <inertia ixx="0.000283315" ixy="1.0793e-07" ixz="-7.05555e-10" iyy="0.000294049" iyz="-6.32939e-09" izz="0.00010571"/>
    </inertial>
    <visual>
      <origin xyz="0 0 -0.599" rpy="0 0 0"/>
      <geometry>
        <mesh filename="package://aero_description/models/aero_arm_meshes/SEED-ARM_wrist-y.stl"scale="0.001 0.001 0.001"/>
      </geometry>
      <material name="Link6_1_color">
        <color rgba="0.74902 0.74902 0.74902 1.0"/>
      </material>
    </visual>
    <collision>
      <origin xyz="0 0 -0.599" rpy="0 0 0"/>
      <geometry>
        <mesh filename="package://aero_description/models/aero_arm_meshes/SEED-ARM_wrist-y.stl"scale="0.001 0.001 0.001"/>
      </geometry>
    </collision>
  </link>
  <joint name="r_wrist_y_joint" type="continuous">
    <origin xyz="0 0 0.1185" rpy="0 0 0"/>
	<axis xyz="0.0 0.0 1.0"/>
    <parent link="r_forearm_link"/>
    <child link="r_wrist_y_link"/>
    <dynamics damping="0.1"/>
  </joint>
  <link name="r_wrist_p_link">
    <inertial>
      <origin xyz="0 0 0" rpy="0 0 0"/>
      <mass value="0.0107199"/>
      <inertia ixx="8.11556e-07" ixy="6.42641e-18" ixz="-2.3405e-12" iyy="7.1075e-07" iyz="0.0" izz="1.21394e-06"/>
    </inertial>
    <visual>
      <origin xyz="0 0 -0.7307" rpy="0 0 0"/>
      <geometry>
        <mesh filename="package://aero_description/models/aero_arm_meshes/SEED-ARM_wrist-p.stl"scale="0.001 0.001 0.001"/>
      </geometry>
      <material name="Link7_1_color">
        <color rgba="0.74902 0.74902 0.74902 1.0"/>
      </material>
    </visual>
    <collision>
      <origin xyz="0 0 -0.7307" rpy="0 0 0"/>
      <geometry>
        <mesh filename="package://aero_description/models/aero_arm_meshes/SEED-ARM_wrist-p.stl"scale="0.001 0.001 0.001"/>
      </geometry>
    </collision>
  </link>
  <joint name="r_wrist_p_joint" type="continuous">
    <origin xyz="0 0 0.1317" rpy="0 0 0"/>
	<axis xyz="1.0 0.0 0.0"/>
    <parent link="r_wrist_y_link"/>
    <child link="r_wrist_p_link"/>
    <dynamics damping="0.1"/>
  </joint>
  <link name="r_wrist_r_link">
    <inertial>
      <origin xyz="0 0 0" rpy="0 0 0"/>
      <mass value="0.0243935"/>
      <inertia ixx="4.82484e-06" ixy="0.0" ixz="7.12872e-18" iyy="6.88455e-06" iyz="3.68181e-07" izz="7.01069e-06"/>
    </inertial>
    <visual>
      <origin xyz="0 0 0" rpy="-1.570796 0 0"/>
      <geometry>
        <mesh filename="package://aero_description/models/aero_arm_meshes/SEED-ARM_wrist-r.stl"scale="0.001 0.001 0.001"/>
      </geometry>
      <material name="Link8_1_color">
        <color rgba="0.74902 0.74902 0.74902 1.0"/>
      </material>
    </visual>
    <collision>
      <origin xyz="0 0 0" rpy="-1.570796 0 0"/>
      <geometry>
        <mesh filename="package://aero_description/models/aero_arm_meshes/SEED-ARM_wrist-r.stl"scale="0.001 0.001 0.001"/>
      </geometry>
    </collision>
  </link>
  <joint name="r_wrist_r_joint" type="continuous">
    <origin xyz="0 0 0" rpy="0 0 0"/>
	<axis xyz="0.0 1.0 0.0"/>
    <parent link="r_wrist_p_link"/>
    <child link="r_wrist_r_link"/>
    <dynamics damping="0.1"/>
  </joint>
  <link name="r_hand_link">
    <visual>
      <origin xyz="0 0 0" rpy="0 -0 0"/>
      <geometry>
        <mesh filename="package://aero_description/models/aero_upper_meshes/RARM_LINK7_mesh.dae" scale="1 1 1" />
      </geometry>
    </visual>
    <collision>
      <origin xyz="0 0 0" rpy="0 -0 0"/>
      <geometry>
        <mesh filename="package://aero_description/models/aero_upper_meshes/RARM_LINK7_mesh.dae" scale="1 1 1" />
      </geometry>
    </collision>
    <inertial>
      <mass value="0.183" />
      <origin xyz="0 0 -0.0875" rpy="0 -0 0"/>
      <inertia ixx="0.000601" ixy="0" ixz="0" iyy="0.00055" iyz="0" izz="0.000102"/>
    </inertial>
  </link>
  <gazebo reference="r_hand_link">
    <mu1>0.9</mu1>
    <mu2>0.9</mu2>
  </gazebo>
  <link name="r_thumb_link">
    <visual>
      <origin xyz="0 -0.013 -0.1358" rpy="0 -0 0"/>
      <geometry>
        <mesh filename="package://aero_description/models/aero_upper_meshes/RARM_INDEX_LINK1_mesh.dae" scale="1 1 1" />
      </geometry>
    </visual>
    <collision>
      <origin xyz="0 -0.013 -0.1358" rpy="0 -0 0"/>
      <geometry>
        <mesh filename="package://aero_description/models/aero_upper_meshes/RARM_INDEX_LINK1_mesh.dae" scale="1 1 1" />
      </geometry>
    </collision>
    <inertial>
      <mass value="0" />
      <origin xyz="0 0 0" rpy="0 -0 0"/>
      <inertia ixx="0" ixy="0" ixz="0" iyy="0" iyz="0" izz="0"/>
    </inertial>
  </link>
  <gazebo reference="r_thumb_link">
    <mu1>0.9</mu1>
    <mu2>0.9</mu2>
  </gazebo>
  <link name="r_indexbase_link">
    <visual>
      <origin xyz="0 0.02912 -0.0343" rpy="0 -0 0"/>
      <geometry>
        <mesh filename="package://aero_description/models/aero_upper_meshes/RARM_INDEX_LINK2_mesh.dae" scale="1 1 1" />
      </geometry>
    </visual>
    <collision>
      <origin xyz="0 0.02912 -0.0343" rpy="0 -0 0"/>
      <geometry>
        <mesh filename="package://aero_description/models/aero_upper_meshes/RARM_INDEX_LINK2_mesh.dae" scale="1 1 1" />
      </geometry>
    </collision>
    <inertial>
      <mass value="0" />
      <origin xyz="0 0 0" rpy="0 -0 0"/>
      <inertia ixx="0" ixy="0" ixz="0" iyy="0" iyz="0" izz="0"/>
    </inertial>
  </link>
  <gazebo reference="r_indexbase_link">
    <mu1>0.9</mu1>
    <mu2>0.9</mu2>
  </gazebo>
  <link name="r_indexmid_link">
    <visual>
      <origin xyz="0 0.02186 -0.0131" rpy="0 -0 0"/>
      <geometry>
        <mesh filename="package://aero_description/models/aero_upper_meshes/RARM_INDEX_LINK3_mesh.dae" scale="1 1 1" />
      </geometry>
    </visual>
    <collision>
      <origin xyz="0 0.02186 -0.0131" rpy="0 -0 0"/>
      <geometry>
        <mesh filename="package://aero_description/models/aero_upper_meshes/RARM_INDEX_LINK3_mesh.dae" scale="1 1 1" />
      </geometry>
    </collision>
    <inertial>
      <mass value="0" />
      <origin xyz="0 0 0" rpy="0 -0 0"/>
      <inertia ixx="0" ixy="0" ixz="0" iyy="0" iyz="0" izz="0"/>
    </inertial>
  </link>
  <gazebo reference="r_indexmid_link">
    <mu1>0.9</mu1>
    <mu2>0.9</mu2>
  </gazebo>
  <link name="r_indexend_link">
    <visual>
      <origin xyz="0 0.0224 -0.1" rpy="0 -0 0"/>
      <geometry>
        <mesh filename="package://aero_description/models/aero_upper_meshes/RARM_THUMB_LINK_mesh.dae" scale="1 1 1" />
      </geometry>
    </visual>
    <collision>
      <origin xyz="0 0.0224 -0.1" rpy="0 -0 0"/>
      <geometry>
        <mesh filename="package://aero_description/models/aero_upper_meshes/RARM_THUMB_LINK_mesh.dae" scale="1 1 1" />
      </geometry>
    </collision>
    <inertial>
      <mass value="0" />
      <origin xyz="0 0 0" rpy="0 -0 0"/>
      <inertia ixx="0" ixy="0" ixz="0" iyy="0" iyz="0" izz="0"/>
    </inertial>
  </link>
  <gazebo reference="r_indexend_link">
    <mu1>0.9</mu1>
    <mu2>0.9</mu2>
  </gazebo>
  <joint name="Assembly_SH_1_Link8_1" type="fixed">
    <origin xyz="0 0 -0.0224" rpy="0 3.14159 -1.570796"/>
    <parent link="r_wrist_r_link"/>
    <child link="r_hand_link"/>
    <dynamics damping="0.1"/>
  </joint>
  <joint name="r_indexbase_joint" type="continuous">
    <parent link="r_hand_link"/>
    <child  link="r_thumb_link"/>
    <origin xyz="0 -0.013 -0.1358" rpy="0 0 0 "/>
    <axis   xyz="1 0 0"/>
    <limit lower="-3.14159" upper="3.14159" effort="100" velocity="0.5" />
    <dynamics damping="0.2" friction="0" />
  </joint>
  <transmission type="pr2_mechanism_model/SimpleTransmission" name="r_indexbase_joint_trans" >
    <actuator name="r_indexbase_joint_motor" />
    <joint name="r_indexbase_joint" />
    <mechanicalReduction>1</mechanicalReduction>
  </transmission>
  <gazebo reference="r_indexbase_joint">
    <cfmDamping>0.4</cfmDamping>
  </gazebo>
  <joint name="r_indexmid_joint" type="continuous">
    <parent link="r_thumb_link"/>
    <child  link="r_indexbase_link"/>
    <origin xyz="0 0.02912 -0.0343" rpy="0 -0 0 "/>
    <axis   xyz="1 0 0"/>
    <limit lower="-3.14159" upper="3.14159" effort="100" velocity="0.5" />
    <dynamics damping="0.2" friction="0" />
  </joint>
  <transmission type="pr2_mechanism_model/SimpleTransmission" name="r_indexmid_joint_trans" >
    <actuator name="r_indexmid_joint_motor" />
    <joint name="r_indexmid_joint" />
    <mechanicalReduction>1</mechanicalReduction>
  </transmission>
  <gazebo reference="r_indexmid_joint">
    <cfmDamping>0.4</cfmDamping>
  </gazebo>
  <joint name="r_indexend_joint" type="continuous">
    <parent link="r_indexbase_link"/>
    <child  link="r_indexmid_link"/>
    <origin xyz="0 0.02186 -0.0131" rpy="0 -0 0 "/>
    <axis   xyz="1 0 0"/>
    <limit lower="-3.14159" upper="3.14159" effort="100" velocity="0.5" />
    <dynamics damping="0.2" friction="0" />
  </joint>
  <transmission type="pr2_mechanism_model/SimpleTransmission" name="r_indexend_joint_trans" >
    <actuator name="r_indexend_joint_motor" />
    <joint name="r_indexend_joint" />
    <mechanicalReduction>1</mechanicalReduction>
  </transmission>
  <gazebo reference="r_indexend_joint">
    <cfmDamping>0.4</cfmDamping>
  </gazebo>
  <joint name="r_thumb_joint" type="continuous">
    <parent link="r_hand_link"/>
    <child  link="r_indexend_link"/>
    <origin xyz="0 0.0224 -0.1" rpy="0 -0 0 "/>
    <axis   xyz="1 0 0"/>
    <limit lower="-3.14159" upper="3.14159" effort="100" velocity="0.5" />
    <dynamics damping="0.2" friction="0" />
  </joint>
  <transmission type="pr2_mechanism_model/SimpleTransmission" name="r_thumb_joint_trans" >
    <actuator name="r_thumb_joint_motor" />
    <joint name="r_thumb_joint" />
    <mechanicalReduction>1</mechanicalReduction>
  </transmission>
  <gazebo reference="r_thumb_joint">
    <cfmDamping>0.4</cfmDamping>
  </gazebo>
<!--
  <link name="Link4_1">
    <inertial>
      <origin xyz="0 0.0291177467702 -1.67202693382e-07" rpy="0 0 0"/>
      <mass value="0.0840688"/>
      <inertia ixx="4.66787e-05" ixy="8.93526e-14" ixz="6.41682e-14" iyy="4.22398e-06" iyz="-9.09596e-07" izz="4.67441e-05"/>
    </inertial>
    <visual>
      <origin xyz="0 0.0582344969321 -2.52113077118e-07" rpy="0 0 0"/>
      <geometry>
        <mesh filename="package://aero_description/models/koizumi_arm_meshes/matlab/koizumi_arm/link4_iam_8bce0ba7.STL"/>
      </geometry>
      <material name="Link4_1_color">
        <color rgba="0.74902 0.74902 0.74902 1.0"/>
      </material>
    </visual>
    <collision>
      <origin xyz="0 0.0582344969321 -2.52113077118e-07" rpy="0 0 0"/>
      <geometry>
        <mesh filename="package://aero_description/models/koizumi_arm_meshes/matlab/koizumi_arm/link4_iam_8bce0ba7.STL"/>
      </geometry>
    </collision>
  </link>
  <joint name="Link4_1_Link2_1" type="continuous">
    <origin xyz="0.00633982815859 0 -0.313594845029" rpy="-2.53560829497 0 -1.57079632679"/>
    <axis xyz="1.0 4.4408920985e-16 -2.08166817117e-17"/>
    <parent link="r_upperarm_link"/>
    <child link="Link4_1"/>
    <dynamics damping="0.1"/>
  </joint>
-->
<joint name="upper_lower_connector" type="continuous">
<parent link="base_link"/>
<child  link="leg_base_link"/>
<origin xyz="0 0 0" rpy="0 -0 0 "/>
<axis   xyz="0 0 1"/>
<limit lower="-3.14159" upper="3.14159" effort="100" velocity="0.5" />
<dynamics damping="0.2" friction="0" />
</joint>
<transmission type="pr2_mechanism_model/SimpleTransmission" name="upper_lower_connector_trans" >
<actuator name="upper_lower_connector_motor" />
<joint name="upper_lower_connector" />
<mechanicalReduction>1</mechanicalReduction>
</transmission>
<gazebo reference="upper_lower_connector">
<cfmDamping>0.4</cfmDamping>
</gazebo>
<joint name="hip_joint" type="revolute">
<parent link="leg_base_link"/>
<child  link="leg_thigh_link"/>
<origin xyz="0.0 0.0 -0.05" rpy="0 -0 0 "/>
<axis   xyz="0 1 0"/>
<limit lower="0" upper="1.5708" effort="100" velocity="0.5" />
<dynamics damping="0.2" friction="0" />
</joint>
<transmission type="pr2_mechanism_model/SimpleTransmission" name="hip_joint_trans" >
<actuator name="hip_joint_motor" />
<joint name="hip_joint" />
<mechanicalReduction>1</mechanicalReduction>
</transmission>
<gazebo reference="hip_joint">
<cfmDamping>0.4</cfmDamping>
</gazebo>
<joint name="knee_joint" type="revolute">
<parent link="leg_thigh_link"/>
<child  link="leg_foreleg_link"/>
<origin xyz="0.0212 0.0 -0.29" rpy="0 -0 0 "/>
<axis   xyz="0 -1 0"/>
<limit lower="0" upper="1.5708" effort="100" velocity="0.5" />
<dynamics damping="0.2" friction="0" />
</joint>
<transmission type="pr2_mechanism_model/SimpleTransmission" name="knee_joint_trans" >
<actuator name="knee_joint_motor" />
<joint name="knee_joint" />
<mechanicalReduction>1</mechanicalReduction>
</transmission>
<gazebo reference="knee_joint">
<cfmDamping>0.4</cfmDamping>
</gazebo>
</robot>

