<?xml version="1.0"?>
<robot name="AeroLowerRobot"
       xmlns:xi="http://www.w3.org/2001/XInclude"
       xmlns:gazebo="http://playerstage.sourceforge.net/gazebo/xmlschema/#gz"
       xmlns:model="http://playerstage.sourceforge.net/gazebo/xmlschema/#model"
       xmlns:sensor="http://playerstage.sourceforge.net/gazebo/xmlschema/#sensor"
       xmlns:body="http://playerstage.sourceforge.net/gazebo/xmlschema/#body"
       xmlns:geom="http://playerstage.sourceforge.net/gazebo/xmlschema/#geom"
       xmlns:joint="http://playerstage.sourceforge.net/gazebo/xmlschema/#joint"
       xmlns:interface="http://playerstage.sourceforge.net/gazebo/xmlschema/#interface"
       xmlns:rendering="http://playerstage.sourceforge.net/gazebo/xmlschema/#rendering"
       xmlns:renderable="http://playerstage.sourceforge.net/gazebo/xmlschema/#renderable"
       xmlns:controller="http://playerstage.sourceforge.net/gazebo/xmlschema/#controller"
       xmlns:physics="http://playerstage.sourceforge.net/gazebo/xmlschema/#physics">
  <link name="WAIST_LINK0">
    <visual>
      <origin xyz="0 0 0.7235" rpy="0 -0 0"/>
      <geometry>
        <mesh filename="package://aero_description/models/aero-lower_meshes/WAIST_LINK0_mesh.dae" scale="1 1 1" />
      </geometry>
    </visual>
    <collision>
      <origin xyz="0 0 0.7235" rpy="0 -0 0"/>
      <geometry>
        <mesh filename="package://aero_description/models/aero-lower_meshes/WAIST_LINK0_mesh.dae" scale="1 1 1" />
      </geometry>
    </collision>
    <inertial>
      <mass value="0" />
      <origin xyz="0 0 0" rpy="0 -0 0"/>
      <inertia ixx="0" ixy="0" ixz="0" iyy="0" iyz="0" izz="0"/>
    </inertial>
  </link>
  <gazebo reference="WAIST_LINK0">
    <mu1>0.9</mu1>
    <mu2>0.9</mu2>
  </gazebo>
  <link name="WAIST_LINK1">
    <visual>
      <origin xyz="0 0 -0.01" rpy="0 -0 0"/>
      <geometry>
        <mesh filename="package://aero_description/models/aero_arm_meshes/CRT_arm_base_plate.stl" scale="0.001 0.001 0.001"/>
      </geometry>
    </visual>
      <material name="Assy_WAIST_LINK1_color">
        <color rgba="0.74902 0.74902 0.74902 1.0"/>
      </material>
    <collision>
      <origin xyz="0 0 -0.01" rpy="0 -0 0"/>
      <geometry>
        <mesh filename="package://aero_description/models/aero_arm_meshes/CRT_arm_base_plate.stl" scale="0.001 0.001 0.001"/>
      </geometry>
    </collision>
    <inertial>
      <mass value="7.64604" />
      <origin xyz="-0.012819 -0.002679 0.007207" rpy="0 -0 0"/>
      <inertia ixx="0.0658136" ixy="-0.000159462" ixz="0.010103" iyy="0.0504268" iyz="0.000173435" izz="0.0889772"/>
    </inertial>
  </link>
  <gazebo reference="WAIST_LINK1">
    <mu1>0.9</mu1>
    <mu2>0.9</mu2>
  </gazebo>
  <link name="LEG_LINK1">
    <visual>
      <origin xyz="0.0 0.0 -0.243" rpy="0 -0 0"/>
      <geometry>
        <mesh filename="package://aero_description/models/aero_arm_meshes/Lifter_thigh.stl" scale="0.001 0.001 0.001"/>
      </geometry>
      <material name="Assy_LEG_LINK1_color">
        <color rgba="0.6 0.6 0.6 1.0"/>
      </material>
    </visual>
    <collision>
      <origin xyz="0.0 0.0 -0.243" rpy="0 -0 0"/>
      <geometry>
       <mesh filename="package://aero_description/models/aero_arm_meshes/Lifter_thigh.stl" scale="0.001 0.001 0.001"/>
      </geometry>
    </collision>
    <inertial>
      <mass value="2.62321" />
      <origin xyz="0.0587169 0 -0.135292" rpy="0 -0 0"/>
      <inertia ixx="0.0161595" ixy="-9.27234e-05" ixz="0.00262839" iyy="0.0166415" iyz="-0.00017447" izz="0.00477281"/>
    </inertial>
  </link>
  <gazebo reference="LEG_LINK1">
    <mu1>0.9</mu1>
    <mu2>0.9</mu2>
  </gazebo>
  <link name="LEG_LINK2">
    <visual>
      <origin xyz="-0.0212 0.0 0.04" rpy="0 -0 0"/>
      <geometry>
       <mesh filename="package://aero_description/models/aero_arm_meshes/Lifter_foreleg.stl" scale="0.001 0.001 0.001"/>
      </geometry>
      <material name="Assy_LEG_LINK2_color">
        <color rgba="0.8 0.8 0.8 1.0"/>
      </material>
    </visual>
    <collision>
      <origin xyz="-0.0212 0.0 0.045" rpy="0 -0 0"/>
      <geometry>
       <mesh filename="package://aero_description/models/aero_arm_meshes/Lifter_foreleg.stl" scale="0.001 0.001 0.001"/>
      </geometry>
    </collision>
    <inertial>
      <mass value="2.06679" />
      <origin xyz="0.081713 0.000812 -0.146934" rpy="0 -0 0"/>
      <inertia ixx="0.0408818" ixy="-9.39301e-06" ixz="-0.000750165" iyy="0.0403969" iyz="-0.000120419" izz="0.00260982"/>
    </inertial>
  </link>
  <gazebo reference="LEG_LINK2">
    <mu1>0.9</mu1>
    <mu2>0.9</mu2>
  </gazebo>

  <joint name="WAIST_Y" type="continuous">
    <parent link="WAIST_LINK0"/>
    <child  link="WAIST_LINK1"/>
    <origin xyz="0 0 0" rpy="0 -0 0 "/>
    <axis   xyz="0 0 1"/>
    <limit lower="-3.14159" upper="3.14159" effort="100" velocity="0.5" />
    <dynamics damping="0.2" friction="0" />
  </joint>
  <transmission type="pr2_mechanism_model/SimpleTransmission" name="WAIST_Y_trans" >
    <actuator name="WAIST_Y_motor" />
    <joint name="WAIST_Y" />
    <mechanicalReduction>1</mechanicalReduction>
  </transmission>
  <gazebo reference="WAIST_Y">
    <cfmDamping>0.4</cfmDamping>
  </gazebo>
  <joint name="LEG_HIP" type="revolute">
    <parent link="WAIST_LINK1"/>
    <child  link="LEG_LINK1"/>
    <origin xyz="0.0 0.0 -0.05" rpy="0 -0 0 "/>
    <axis   xyz="0 1 0"/>
    <limit lower="0" upper="1.5708" effort="100" velocity="0.5" />
    <dynamics damping="0.2" friction="0" />
  </joint>
  <transmission type="pr2_mechanism_model/SimpleTransmission" name="LEG_HIP_trans" >
    <actuator name="LEG_HIP_motor" />
    <joint name="LEG_HIP" />
    <mechanicalReduction>1</mechanicalReduction>
  </transmission>
  <gazebo reference="LEG_HIP">
    <cfmDamping>0.4</cfmDamping>
  </gazebo>
  <joint name="LEG_KNEE" type="revolute">
    <parent link="LEG_LINK1"/>
    <child  link="LEG_LINK2"/>
    <origin xyz="0.0212 0.0 -0.29" rpy="0 -0 0 "/>
    <axis   xyz="0 -1 0"/>
    <limit lower="0" upper="1.5708" effort="100" velocity="0.5" />
    <dynamics damping="0.2" friction="0" />
  </joint>
  <transmission type="pr2_mechanism_model/SimpleTransmission" name="LEG_KNEE_trans" >
    <actuator name="LEG_KNEE_motor" />
    <joint name="LEG_KNEE" />
    <mechanicalReduction>1</mechanicalReduction>
  </transmission>
  <gazebo reference="LEG_KNEE">
    <cfmDamping>0.4</cfmDamping>
  </gazebo>

</robot>
