<?xml version="1.0"?>
<robot name="AeroLowerRobot"
       xmlns:xi="http://www.w3.org/2001/XInclude"
       xmlns:gazebo="http://playerstage.sourceforge.net/gazebo/xmlschema/#gz"
       xmlns:model="http://playerstage.sourceforge.net/gazebo/xmlschema/#model"
       xmlns:sensor="http://playerstage.sourceforge.net/gazebo/xmlschema/#sensor"
       xmlns:body="http://playerstage.sourceforge.net/gazebo/xmlschema/#body"
       xmlns:geom="http://playerstage.sourceforge.net/gazebo/xmlschema/#geom"
       xmlns:joint="http://playerstage.sourceforge.net/gazebo/xmlschema/#joint"
       xmlns:interface="http://playerstage.sourceforge.net/gazebo/xmlschema/#interface"
       xmlns:rendering="http://playerstage.sourceforge.net/gazebo/xmlschema/#rendering"
       xmlns:renderable="http://playerstage.sourceforge.net/gazebo/xmlschema/#renderable"
       xmlns:controller="http://playerstage.sourceforge.net/gazebo/xmlschema/#controller"
       xmlns:physics="http://playerstage.sourceforge.net/gazebo/xmlschema/#physics">
  <link name="WAIST_LINK0">
    <visual>
      <origin xyz="0 0 0.7235" rpy="0 -0 0"/>
      <geometry>
        <mesh filename="package://aero_description/models/aero-lower_meshes/WAIST_LINK0_mesh.dae" scale="1 1 1" />
      </geometry>
    </visual>
    <collision>
      <origin xyz="0 0 0.7235" rpy="0 -0 0"/>
      <geometry>
        <mesh filename="package://aero_description/models/aero-lower_meshes/WAIST_LINK0_mesh.dae" scale="1 1 1" />
      </geometry>
    </collision>
    <inertial>
      <mass value="0" />
      <origin xyz="0 0 0" rpy="0 -0 0"/>
      <inertia ixx="0" ixy="0" ixz="0" iyy="0" iyz="0" izz="0"/>
    </inertial>
  </link>
  <gazebo reference="WAIST_LINK0">
    <mu1>0.9</mu1>
    <mu2>0.9</mu2>
  </gazebo>
  <link name="WAIST_LINK1">
    <visual>
      <origin xyz="0 0 0" rpy="0 -0 0"/>
      <geometry>
        <mesh filename="package://aero_description/models/aero-lower_meshes/WAIST_LINK1_mesh.dae" scale="1 1 1" />
      </geometry>
    </visual>
    <collision>
      <origin xyz="0 0 0" rpy="0 -0 0"/>
      <geometry>
        <mesh filename="package://aero_description/models/aero-lower_meshes/WAIST_LINK1_mesh.dae" scale="1 1 1" />
      </geometry>
    </collision>
    <inertial>
      <mass value="7.64604" />
      <origin xyz="-0.012819 -0.002679 0.007207" rpy="0 -0 0"/>
      <inertia ixx="0.0658136" ixy="-0.000159462" ixz="0.010103" iyy="0.0504268" iyz="0.000173435" izz="0.0889772"/>
    </inertial>
  </link>
  <gazebo reference="WAIST_LINK1">
    <mu1>0.9</mu1>
    <mu2>0.9</mu2>
  </gazebo>
  <link name="LARM_LINK1">
    <visual>
      <origin xyz="0.06 0.1 -0.087" rpy="0 -0 0"/>
      <geometry>
        <mesh filename="package://aero_description/models/aero-lower_meshes/LARM_LINK1_mesh.dae" scale="1 1 1" />
      </geometry>
    </visual>
    <collision>
      <origin xyz="0.06 0.1 -0.087" rpy="0 -0 0"/>
      <geometry>
        <mesh filename="package://aero_description/models/aero-lower_meshes/LARM_LINK1_mesh.dae" scale="1 1 1" />
      </geometry>
    </collision>
    <inertial>
      <mass value="0.262933" />
      <origin xyz="0.0339853 0.009895 -0.0268937" rpy="0 -0 0"/>
      <inertia ixx="0.000323238" ixy="7.5376e-06" ixz="-4.6651e-06" iyy="0.000199716" iyz="-1.3948e-05" izz="0.000214642"/>
    </inertial>
  </link>
  <gazebo reference="LARM_LINK1">
    <mu1>0.9</mu1>
    <mu2>0.9</mu2>
  </gazebo>
  <link name="LARM_LINK2">
    <visual>
      <origin xyz="0.0338084 0 -0.060551" rpy="0 -0 0"/>
      <geometry>
        <mesh filename="package://aero_description/models/aero-lower_meshes/LARM_LINK2_mesh.dae" scale="1 1 1" />
      </geometry>
    </visual>
    <collision>
      <origin xyz="0.0338084 0 -0.060551" rpy="0 -0 0"/>
      <geometry>
        <mesh filename="package://aero_description/models/aero-lower_meshes/LARM_LINK2_mesh.dae" scale="1 1 1" />
      </geometry>
    </collision>
    <inertial>
      <mass value="2.62321" />
      <origin xyz="0.0587169 0 -0.135292" rpy="0 -0 0"/>
      <inertia ixx="0.0161595" ixy="-9.27234e-05" ixz="0.00262839" iyy="0.0166415" iyz="-0.00017447" izz="0.00477281"/>
    </inertial>
  </link>
  <gazebo reference="LARM_LINK2">
    <mu1>0.9</mu1>
    <mu2>0.9</mu2>
  </gazebo>
  <link name="LARM_LINK3">
    <visual>
      <origin xyz="0.150005 0 -0.259808" rpy="0 -0 0"/>
      <geometry>
        <mesh filename="package://aero_description/models/aero-lower_meshes/LARM_LINK3_mesh.dae" scale="1 1 1" />
      </geometry>
    </visual>
    <collision>
      <origin xyz="0.150005 0 -0.259808" rpy="0 -0 0"/>
      <geometry>
        <mesh filename="package://aero_description/models/aero-lower_meshes/LARM_LINK3_mesh.dae" scale="1 1 1" />
      </geometry>
    </collision>
    <inertial>
      <mass value="2.06679" />
      <origin xyz="0.081713 0.000812 -0.146934" rpy="0 -0 0"/>
      <inertia ixx="0.0408818" ixy="-9.39301e-06" ixz="-0.000750165" iyy="0.0403969" iyz="-0.000120419" izz="0.00260982"/>
    </inertial>
  </link>
  <gazebo reference="LARM_LINK3">
    <mu1>0.9</mu1>
    <mu2>0.9</mu2>
  </gazebo>
  <link name="LLEG_LINK1">
    <visual>
      <origin xyz="-0.06 0.1 -0.087" rpy="0 -0 3.14159"/>
      <geometry>
        <mesh filename="package://aero_description/models/aero-lower_meshes/LLEG_LINK1_mesh.dae" scale="1 1 1" />
      </geometry>
    </visual>
    <collision>
      <origin xyz="-0.06 0.1 -0.087" rpy="0 -0 3.14159"/>
      <geometry>
        <mesh filename="package://aero_description/models/aero-lower_meshes/LLEG_LINK1_mesh.dae" scale="1 1 1" />
      </geometry>
    </collision>
    <inertial>
      <mass value="0.262933" />
      <origin xyz="0.0339853 -0.009895 -0.0268937" rpy="0 -0 0"/>
      <inertia ixx="0.000323238" ixy="7.5376e-06" ixz="-4.6651e-06" iyy="0.000199716" iyz="-1.3948e-05" izz="0.000214642"/>
    </inertial>
  </link>
  <gazebo reference="LLEG_LINK1">
    <mu1>0.9</mu1>
    <mu2>0.9</mu2>
  </gazebo>
  <link name="LLEG_LINK2">
    <visual>
      <origin xyz="0.0338084 0 -0.060551" rpy="0 -0 0"/>
      <geometry>
        <mesh filename="package://aero_description/models/aero-lower_meshes/LLEG_LINK2_mesh.dae" scale="1 1 1" />
      </geometry>
    </visual>
    <collision>
      <origin xyz="0.0338084 0 -0.060551" rpy="0 -0 0"/>
      <geometry>
        <mesh filename="package://aero_description/models/aero-lower_meshes/LLEG_LINK2_mesh.dae" scale="1 1 1" />
      </geometry>
    </collision>
    <inertial>
      <mass value="2.62321" />
      <origin xyz="0.0587169 1.38778e-17 -0.135292" rpy="0 -0 0"/>
      <inertia ixx="0.0161595" ixy="-9.27234e-05" ixz="0.00262839" iyy="0.0166415" iyz="-0.00017447" izz="0.00477281"/>
    </inertial>
  </link>
  <gazebo reference="LLEG_LINK2">
    <mu1>0.9</mu1>
    <mu2>0.9</mu2>
  </gazebo>
  <link name="LLEG_LINK3">
    <visual>
      <origin xyz="0.150005 0 -0.259808" rpy="0 -0 0"/>
      <geometry>
        <mesh filename="package://aero_description/models/aero-lower_meshes/LLEG_LINK3_mesh.dae" scale="1 1 1" />
      </geometry>
    </visual>
    <collision>
      <origin xyz="0.150005 0 -0.259808" rpy="0 -0 0"/>
      <geometry>
        <mesh filename="package://aero_description/models/aero-lower_meshes/LLEG_LINK3_mesh.dae" scale="1 1 1" />
      </geometry>
    </collision>
    <inertial>
      <mass value="2.06679" />
      <origin xyz="0.081713 0.000812 -0.146934" rpy="0 -0 0"/>
      <inertia ixx="0.0408818" ixy="-9.39301e-06" ixz="-0.000750165" iyy="0.0403969" iyz="-0.000120419" izz="0.00260982"/>
    </inertial>
  </link>
  <gazebo reference="LLEG_LINK3">
    <mu1>0.9</mu1>
    <mu2>0.9</mu2>
  </gazebo>
  <link name="RARM_LINK1">
    <visual>
      <origin xyz="0.06 -0.1 -0.087" rpy="0 -0 0"/>
      <geometry>
        <mesh filename="package://aero_description/models/aero-lower_meshes/RARM_LINK1_mesh.dae" scale="1 1 1" />
      </geometry>
    </visual>
    <collision>
      <origin xyz="0.06 -0.1 -0.087" rpy="0 -0 0"/>
      <geometry>
        <mesh filename="package://aero_description/models/aero-lower_meshes/RARM_LINK1_mesh.dae" scale="1 1 1" />
      </geometry>
    </collision>
    <inertial>
      <mass value="0.262933" />
      <origin xyz="0.0339853 -0.009895 -0.0268937" rpy="0 -0 0"/>
      <inertia ixx="0.000323238" ixy="7.5376e-06" ixz="-4.6651e-06" iyy="0.000199716" iyz="-1.3948e-05" izz="0.000214642"/>
    </inertial>
  </link>
  <gazebo reference="RARM_LINK1">
    <mu1>0.9</mu1>
    <mu2>0.9</mu2>
  </gazebo>
  <link name="RARM_LINK2">
    <visual>
      <origin xyz="0.0338084 0 -0.060551" rpy="0 -0 0"/>
      <geometry>
        <mesh filename="package://aero_description/models/aero-lower_meshes/RARM_LINK2_mesh.dae" scale="1 1 1" />
      </geometry>
    </visual>
    <collision>
      <origin xyz="0.0338084 0 -0.060551" rpy="0 -0 0"/>
      <geometry>
        <mesh filename="package://aero_description/models/aero-lower_meshes/RARM_LINK2_mesh.dae" scale="1 1 1" />
      </geometry>
    </collision>
    <inertial>
      <mass value="2.62321" />
      <origin xyz="0.0587169 0 -0.135292" rpy="0 -0 0"/>
      <inertia ixx="0.0161595" ixy="-9.27234e-05" ixz="0.00262839" iyy="0.0166415" iyz="-0.00017447" izz="0.00477281"/>
    </inertial>
  </link>
  <gazebo reference="RARM_LINK2">
    <mu1>0.9</mu1>
    <mu2>0.9</mu2>
  </gazebo>
  <link name="RARM_LINK3">
    <visual>
      <origin xyz="0.150005 0 -0.259808" rpy="0 -0 0"/>
      <geometry>
        <mesh filename="package://aero_description/models/aero-lower_meshes/RARM_LINK3_mesh.dae" scale="1 1 1" />
      </geometry>
    </visual>
    <collision>
      <origin xyz="0.150005 0 -0.259808" rpy="0 -0 0"/>
      <geometry>
        <mesh filename="package://aero_description/models/aero-lower_meshes/RARM_LINK3_mesh.dae" scale="1 1 1" />
      </geometry>
    </collision>
    <inertial>
      <mass value="2.06679" />
      <origin xyz="0.081713 -0.000812 -0.146934" rpy="0 -0 0"/>
      <inertia ixx="0.0408818" ixy="-9.39301e-06" ixz="-0.000750165" iyy="0.0403969" iyz="-0.000120419" izz="0.00260982"/>
    </inertial>
  </link>
  <gazebo reference="RARM_LINK3">
    <mu1>0.9</mu1>
    <mu2>0.9</mu2>
  </gazebo>
  <link name="RLEG_LINK1">
    <visual>
      <origin xyz="-0.06 -0.1 -0.087" rpy="0 -0 3.14159"/>
      <geometry>
        <mesh filename="package://aero_description/models/aero-lower_meshes/RLEG_LINK1_mesh.dae" scale="1 1 1" />
      </geometry>
    </visual>
    <collision>
      <origin xyz="-0.06 -0.1 -0.087" rpy="0 -0 3.14159"/>
      <geometry>
        <mesh filename="package://aero_description/models/aero-lower_meshes/RLEG_LINK1_mesh.dae" scale="1 1 1" />
      </geometry>
    </collision>
    <inertial>
      <mass value="0.262933" />
      <origin xyz="0.0339853 0.009895 -0.0268937" rpy="0 -0 0"/>
      <inertia ixx="0.000323238" ixy="7.5376e-06" ixz="-4.6651e-06" iyy="0.000199716" iyz="-1.3948e-05" izz="0.000214642"/>
    </inertial>
  </link>
  <gazebo reference="RLEG_LINK1">
    <mu1>0.9</mu1>
    <mu2>0.9</mu2>
  </gazebo>
  <link name="RLEG_LINK2">
    <visual>
      <origin xyz="0.0338084 0 -0.060551" rpy="0 -0 0"/>
      <geometry>
        <mesh filename="package://aero_description/models/aero-lower_meshes/RLEG_LINK2_mesh.dae" scale="1 1 1" />
      </geometry>
    </visual>
    <collision>
      <origin xyz="0.0338084 0 -0.060551" rpy="0 -0 0"/>
      <geometry>
        <mesh filename="package://aero_description/models/aero-lower_meshes/RLEG_LINK2_mesh.dae" scale="1 1 1" />
      </geometry>
    </collision>
    <inertial>
      <mass value="2.62321" />
      <origin xyz="0.0587169 1.38778e-17 -0.135292" rpy="0 -0 0"/>
      <inertia ixx="0.0161595" ixy="-9.27234e-05" ixz="0.00262839" iyy="0.0166415" iyz="-0.00017447" izz="0.00477281"/>
    </inertial>
  </link>
  <gazebo reference="RLEG_LINK2">
    <mu1>0.9</mu1>
    <mu2>0.9</mu2>
  </gazebo>
  <link name="RLEG_LINK3">
    <visual>
      <origin xyz="0.150005 0 -0.259808" rpy="0 -0 0"/>
      <geometry>
        <mesh filename="package://aero_description/models/aero-lower_meshes/RLEG_LINK3_mesh.dae" scale="1 1 1" />
      </geometry>
    </visual>
    <collision>
      <origin xyz="0.150005 0 -0.259808" rpy="0 -0 0"/>
      <geometry>
        <mesh filename="package://aero_description/models/aero-lower_meshes/RLEG_LINK3_mesh.dae" scale="1 1 1" />
      </geometry>
    </collision>
    <inertial>
      <mass value="2.06679" />
      <origin xyz="0.081713 0.000812 -0.146934" rpy="0 -0 0"/>
      <inertia ixx="0.0408818" ixy="-9.39301e-06" ixz="-0.000750165" iyy="0.0403969" iyz="-0.000120419" izz="0.00260982"/>
    </inertial>
  </link>
  <gazebo reference="RLEG_LINK3">
    <mu1>0.9</mu1>
    <mu2>0.9</mu2>
  </gazebo>
  <joint name="WAIST_Y" type="continuous">
    <parent link="WAIST_LINK0"/>
    <child  link="WAIST_LINK1"/>
    <origin xyz="0 0 0" rpy="0 -0 0 "/>
    <axis   xyz="0 0 1"/>
    <limit lower="-3.14159" upper="3.14159" effort="100" velocity="0.5" />
    <dynamics damping="0.2" friction="0" />
  </joint>
  <transmission type="pr2_mechanism_model/SimpleTransmission" name="WAIST_Y_trans" >
    <actuator name="WAIST_Y_motor" />
    <joint name="WAIST_Y" />
    <mechanicalReduction>1</mechanicalReduction>
  </transmission>
  <gazebo reference="WAIST_Y">
    <cfmDamping>0.4</cfmDamping>
  </gazebo>
  <joint name="LARM_SHOULDER_Y" type="continuous">
    <parent link="WAIST_LINK1"/>
    <child  link="LARM_LINK1"/>
    <origin xyz="0.06 0.1 -0.087" rpy="0 -0 0 "/>
    <axis   xyz="0 0 1"/>
    <limit lower="-3.14159" upper="3.14159" effort="100" velocity="0.5" />
    <dynamics damping="0.2" friction="0" />
  </joint>
  <transmission type="pr2_mechanism_model/SimpleTransmission" name="LARM_SHOULDER_Y_trans" >
    <actuator name="LARM_SHOULDER_Y_motor" />
    <joint name="LARM_SHOULDER_Y" />
    <mechanicalReduction>1</mechanicalReduction>
  </transmission>
  <gazebo reference="LARM_SHOULDER_Y">
    <cfmDamping>0.4</cfmDamping>
  </gazebo>
  <joint name="LARM_SHOULDER_P" type="revolute">
    <parent link="LARM_LINK1"/>
    <child  link="LARM_LINK2"/>
    <origin xyz="0.0338084 0 -0.060551" rpy="0 -0 0 "/>
    <axis   xyz="0 -1 0"/>
    <limit lower="0" upper="1.5708" effort="100" velocity="0.5" />
    <dynamics damping="0.2" friction="0" />
  </joint>
  <transmission type="pr2_mechanism_model/SimpleTransmission" name="LARM_SHOULDER_P_trans" >
    <actuator name="LARM_SHOULDER_P_motor" />
    <joint name="LARM_SHOULDER_P" />
    <mechanicalReduction>1</mechanicalReduction>
  </transmission>
  <gazebo reference="LARM_SHOULDER_P">
    <cfmDamping>0.4</cfmDamping>
  </gazebo>
  <joint name="LARM_ELBOW" type="revolute">
    <parent link="LARM_LINK2"/>
    <child  link="LARM_LINK3"/>
    <origin xyz="0.150005 0 -0.259808" rpy="0 -0 0 "/>
    <axis   xyz="0 1 0"/>
    <limit lower="0" upper="2.79252" effort="100" velocity="0.5" />
    <dynamics damping="0.2" friction="0" />
  </joint>
  <transmission type="pr2_mechanism_model/SimpleTransmission" name="LARM_ELBOW_trans" >
    <actuator name="LARM_ELBOW_motor" />
    <joint name="LARM_ELBOW" />
    <mechanicalReduction>1</mechanicalReduction>
  </transmission>
  <gazebo reference="LARM_ELBOW">
    <cfmDamping>0.4</cfmDamping>
  </gazebo>
  <joint name="LLEG_HIP_Y" type="continuous">
    <parent link="WAIST_LINK1"/>
    <child  link="LLEG_LINK1"/>
    <origin xyz="-0.06 0.1 -0.087" rpy="0 -0 3.14159 "/>
    <axis   xyz="0 0 1"/>
    <limit lower="-3.14159" upper="3.14159" effort="100" velocity="0.5" />
    <dynamics damping="0.2" friction="0" />
  </joint>
  <transmission type="pr2_mechanism_model/SimpleTransmission" name="LLEG_HIP_Y_trans" >
    <actuator name="LLEG_HIP_Y_motor" />
    <joint name="LLEG_HIP_Y" />
    <mechanicalReduction>1</mechanicalReduction>
  </transmission>
  <gazebo reference="LLEG_HIP_Y">
    <cfmDamping>0.4</cfmDamping>
  </gazebo>
  <joint name="LLEG_HIP_P" type="revolute">
    <parent link="LLEG_LINK1"/>
    <child  link="LLEG_LINK2"/>
    <origin xyz="0.0338084 0 -0.060551" rpy="0 -0 0 "/>
    <axis   xyz="0 -1 0"/>
    <limit lower="0" upper="1.5708" effort="100" velocity="0.5" />
    <dynamics damping="0.2" friction="0" />
  </joint>
  <transmission type="pr2_mechanism_model/SimpleTransmission" name="LLEG_HIP_P_trans" >
    <actuator name="LLEG_HIP_P_motor" />
    <joint name="LLEG_HIP_P" />
    <mechanicalReduction>1</mechanicalReduction>
  </transmission>
  <gazebo reference="LLEG_HIP_P">
    <cfmDamping>0.4</cfmDamping>
  </gazebo>
  <joint name="LLEG_KNEE" type="revolute">
    <parent link="LLEG_LINK2"/>
    <child  link="LLEG_LINK3"/>
    <origin xyz="0.150005 0 -0.259808" rpy="0 -0 0 "/>
    <axis   xyz="0 1 0"/>
    <limit lower="0" upper="2.79252" effort="100" velocity="0.5" />
    <dynamics damping="0.2" friction="0" />
  </joint>
  <transmission type="pr2_mechanism_model/SimpleTransmission" name="LLEG_KNEE_trans" >
    <actuator name="LLEG_KNEE_motor" />
    <joint name="LLEG_KNEE" />
    <mechanicalReduction>1</mechanicalReduction>
  </transmission>
  <gazebo reference="LLEG_KNEE">
    <cfmDamping>0.4</cfmDamping>
  </gazebo>
  <joint name="RARM_SHOULDER_Y" type="continuous">
    <parent link="WAIST_LINK1"/>
    <child  link="RARM_LINK1"/>
    <origin xyz="0.06 -0.1 -0.087" rpy="0 -0 0 "/>
    <axis   xyz="0 0 1"/>
    <limit lower="-3.14159" upper="3.14159" effort="100" velocity="0.5" />
    <dynamics damping="0.2" friction="0" />
  </joint>
  <transmission type="pr2_mechanism_model/SimpleTransmission" name="RARM_SHOULDER_Y_trans" >
    <actuator name="RARM_SHOULDER_Y_motor" />
    <joint name="RARM_SHOULDER_Y" />
    <mechanicalReduction>1</mechanicalReduction>
  </transmission>
  <gazebo reference="RARM_SHOULDER_Y">
    <cfmDamping>0.4</cfmDamping>
  </gazebo>
  <joint name="RARM_SHOULDER_P" type="revolute">
    <parent link="RARM_LINK1"/>
    <child  link="RARM_LINK2"/>
    <origin xyz="0.0338084 0 -0.060551" rpy="0 -0 0 "/>
    <axis   xyz="0 -1 0"/>
    <limit lower="0" upper="1.5708" effort="100" velocity="0.5" />
    <dynamics damping="0.2" friction="0" />
  </joint>
  <transmission type="pr2_mechanism_model/SimpleTransmission" name="RARM_SHOULDER_P_trans" >
    <actuator name="RARM_SHOULDER_P_motor" />
    <joint name="RARM_SHOULDER_P" />
    <mechanicalReduction>1</mechanicalReduction>
  </transmission>
  <gazebo reference="RARM_SHOULDER_P">
    <cfmDamping>0.4</cfmDamping>
  </gazebo>
  <joint name="RARM_ELBOW" type="revolute">
    <parent link="RARM_LINK2"/>
    <child  link="RARM_LINK3"/>
    <origin xyz="0.150005 0 -0.259808" rpy="0 -0 0 "/>
    <axis   xyz="0 1 0"/>
    <limit lower="0" upper="2.79252" effort="100" velocity="0.5" />
    <dynamics damping="0.2" friction="0" />
  </joint>
  <transmission type="pr2_mechanism_model/SimpleTransmission" name="RARM_ELBOW_trans" >
    <actuator name="RARM_ELBOW_motor" />
    <joint name="RARM_ELBOW" />
    <mechanicalReduction>1</mechanicalReduction>
  </transmission>
  <gazebo reference="RARM_ELBOW">
    <cfmDamping>0.4</cfmDamping>
  </gazebo>
  <joint name="RLEG_HIP_Y" type="continuous">
    <parent link="WAIST_LINK1"/>
    <child  link="RLEG_LINK1"/>
    <origin xyz="-0.06 -0.1 -0.087" rpy="0 -0 3.14159 "/>
    <axis   xyz="0 0 1"/>
    <limit lower="-3.14159" upper="3.14159" effort="100" velocity="0.5" />
    <dynamics damping="0.2" friction="0" />
  </joint>
  <transmission type="pr2_mechanism_model/SimpleTransmission" name="RLEG_HIP_Y_trans" >
    <actuator name="RLEG_HIP_Y_motor" />
    <joint name="RLEG_HIP_Y" />
    <mechanicalReduction>1</mechanicalReduction>
  </transmission>
  <gazebo reference="RLEG_HIP_Y">
    <cfmDamping>0.4</cfmDamping>
  </gazebo>
  <joint name="RLEG_HIP_P" type="revolute">
    <parent link="RLEG_LINK1"/>
    <child  link="RLEG_LINK2"/>
    <origin xyz="0.0338084 0 -0.060551" rpy="0 -0 0 "/>
    <axis   xyz="0 -1 0"/>
    <limit lower="0" upper="1.5708" effort="100" velocity="0.5" />
    <dynamics damping="0.2" friction="0" />
  </joint>
  <transmission type="pr2_mechanism_model/SimpleTransmission" name="RLEG_HIP_P_trans" >
    <actuator name="RLEG_HIP_P_motor" />
    <joint name="RLEG_HIP_P" />
    <mechanicalReduction>1</mechanicalReduction>
  </transmission>
  <gazebo reference="RLEG_HIP_P">
    <cfmDamping>0.4</cfmDamping>
  </gazebo>
  <joint name="RLEG_KNEE" type="revolute">
    <parent link="RLEG_LINK2"/>
    <child  link="RLEG_LINK3"/>
    <origin xyz="0.150005 0 -0.259808" rpy="0 -0 0 "/>
    <axis   xyz="0 1 0"/>
    <limit lower="0" upper="2.79252" effort="100" velocity="0.5" />
    <dynamics damping="0.2" friction="0" />
  </joint>
  <transmission type="pr2_mechanism_model/SimpleTransmission" name="RLEG_KNEE_trans" >
    <actuator name="RLEG_KNEE_motor" />
    <joint name="RLEG_KNEE" />
    <mechanicalReduction>1</mechanicalReduction>
  </transmission>
  <gazebo reference="RLEG_KNEE">
    <cfmDamping>0.4</cfmDamping>
  </gazebo>
</robot>
