<link name="virtual_lifter_z_link">
</link>
<link name="virtual_lifter_x_link">
</link>
<link name="r_eef_grasp_link">
</link>
<link name="r_eef_pick_link">
</link>
<link name="l_eef_grasp_link">
</link>
<link name="l_eef_pick_link">
</link>
<joint name="virtual_lifter_z_joint" type="prismatic">
  <parent  link="virtual_lifter_z_link"/>
  <child link="base_link"/>
  <origin xyz="0.0 0.0 0.58018" rpy="0 -0 0 "/>
  <axis   xyz="0 0 1"/>
  <limit lower="-0.40" upper="0.0" effort="100" velocity="0.1" />
  <dynamics damping="0.2" friction="0" />
</joint>
<joint name="virtual_lifter_x_joint" type="prismatic">
  <parent link="virtual_lifter_x_link"/>
  <child  link="virtual_lifter_z_link"/>
  <origin xyz="0.0 0.0 -0.0" rpy="0 -0 0 "/>
  <axis   xyz="1 0 0"/>
  <limit lower="-0.2" upper="0.2" effort="100" velocity="0.1" />
  <dynamics damping="0.2" friction="0" />
</joint>
<joint name="r_eef_grasp_joint" type="fixed">
  <parent  link="r_hand_link"/>
  <child link="r_eef_grasp_link"/>
  <origin xyz="0.0 0.04 -0.14" rpy="0 1.5708 0 "/>
</joint>
<joint name="r_eef_pick_joint" type="fixed">
  <parent  link="r_hand_link"/>
  <child link="r_eef_pick_link"/>
  <origin xyz="0.0 0.07 -0.16" rpy="0 1.5708 0 "/>
</joint>
<joint name="l_eef_grasp_joint" type="fixed">
  <parent  link="l_hand_link"/>
  <child link="l_eef_grasp_link"/>
  <origin xyz="0.0 -0.04 -0.14" rpy="0 1.5708 0 "/>
</joint>
<joint name="l_eef_pick_joint" type="fixed">
  <parent  link="l_hand_link"/>
  <child link="l_eef_pick_link"/>
  <origin xyz="0.0 -0.07 -0.16" rpy="0 1.5708 0 "/>
</joint>