<link name="virtual_lifter_z_link">
</link>
<link name="virtual_lifter_x_link">
</link>
<joint name="virtual_lifter_z_joint" type="prismatic">
  <parent  link="virtual_lifter_z_link"/>
  <child link="base_link"/>
  <origin xyz="0.0 0.0 0.7" rpy="0 -0 0 "/>
  <axis   xyz="0 0 1"/>
  <limit lower="-0.40" upper="0.0" effort="100" velocity="0.1" />
  <dynamics damping="0.2" friction="0" />
</joint>
<joint name="virtual_lifter_x_joint" type="prismatic">
  <parent link="virtual_lifter_x_link"/>
  <child  link="virtual_lifter_z_link"/>
  <origin xyz="0.0 0.0 -0.0" rpy="0 -0 0 "/>
  <axis   xyz="1 0 0"/>
  <limit lower="-0.2" upper="0.2" effort="100" velocity="0.1" />
  <dynamics damping="0.2" friction="0" />
</joint>